<?xml version="1.0"?>
<robot  name="2dof_sys" >
 <link  name="world" >
  <inertial >
   <origin  xyz="0.0 0.0 0.0" />
   <mass  value="0.6728687610724418" />
   <inertia  izz="0.0012076389984"  ixz="0"  iyz="0"  ixy="0"  ixx="0.0007034844784"  iyy="0.0012553825394000001" />
  </inertial>
  <visual >
   <origin  xyz="0.0 0.0 0.0" />
   <geometry >
    <mesh  filename="/media/daten/Projekte/Studium/Master/Masterarbeit_SS2024/2DOF_Manipulator/MA24_simulink/stl_files/planar_manipulator-holder_fin.stl"  scale="0.001 0.001 0.001" />
   </geometry>
   <material  name="Grey" >
    <color  rgba="0.5 0.5 0.5 1" />
   </material>
  </visual>
 </link>
 <joint  type="continuous"  name="joint1" >
  <parent  link="world" />
  <child  link="link1" />
 </joint>
 <link  name="link1" >
  <inertial >
   <origin  xyz="0.0 0.0 0.0" />
   <mass  value="0.13201266572070933" />
   <inertia  izz="0.0007536867173"  ixz="0"  iyz="0"  ixy="0"  ixx="1.059561151e-05"  iyy="0.000753829759" />
  </inertial>
  <visual >
   <origin  xyz="0.115 0.0583789 0.0" />
   <geometry >
    <mesh  filename="/media/daten/Projekte/Studium/Master/Masterarbeit_SS2024/2DOF_Manipulator/MA24_simulink/stl_files/planar_manipulator-bulk1_fin.stl"  scale="0.001 0.001 0.001" />
   </geometry>
   <material  name="Orange" >
    <color  rgba="0.97 0.7 0.17 1" />
   </material>
  </visual>
 </link>
 <joint  type="continuous"  name="joint2" >
  <parent  link="link1" />
  <child  link="link2" />
 </joint>
 <link  name="link2" >
  <inertial >
   <origin  xyz="0.0 0.0 0.0" />
   <mass  value="0.18582081864859962" />
   <inertia  izz="0.0008999886885000001"  ixz="0"  iyz="0"  ixy="0"  ixx="2.0154008761000003e-05"  iyy="0.0009063823826" />
  </inertial>
  <visual >
   <origin  xyz="0.353039 0.0583789 0.0" />
   <geometry >
    <mesh  filename="/media/daten/Projekte/Studium/Master/Masterarbeit_SS2024/2DOF_Manipulator/MA24_simulink/stl_files/planar_manipulator-bulk2_fin.stl"  scale="0.001 0.001 0.001" />
   </geometry>
   <material  name="Orange" >
    <color  rgba="0.97 0.7 0.17 1" />
   </material>
  </visual>
 </link>
 
 <gazebo reference="world" >
  <!-- other properties you want to define for the base link -->
  <kinematic> true </kinematic>
</gazebo>
 
</robot>
