<?xml version="1.0" encoding="utf-8"?>
<!-- =================================================================================== -->
<!-- |    This document was autogenerated by xacro from ur5e_with_robotiq_hande.xacro  | -->
<!-- |    EDITING THIS FILE BY HAND IS NOT RECOMMENDED                                 | -->
<!-- =================================================================================== -->
<robot name="ur5e_robot">
  <!--  Author: Cristian C Beltran-Hernandez  -->
  <!-- Source: https://github.com/mcboyd/ur5e_with_robotiq_hande -->

  <!--
    Base UR robot series xacro macro.

    NOTE: this is NOT a URDF. It cannot directly be loaded by consumers
    expecting a flattened '.urdf' file. See the top-level '.xacro' for that
    (but note: that .xacro must still be processed by the xacro command).

    For use in '.launch' files: use one of the 'load_urX.launch' convenience
    launch files.

    This file models the base kinematic chain of a UR robot, which then gets
    parameterised by various configuration files to convert it into a UR3(e),
    UR5(e), UR10(e) or UR16e.

    NOTE: the default kinematic parameters (ie: link lengths, frame locations,
    offets, etc) do not correspond to any particular robot. They are defaults
    only. There WILL be non-zero offsets between the Forward Kinematics results
    in TF (ie: robot_state_publisher) and the values reported by the Teach
    Pendant.

    For accurate (and robot-specific) transforms, the 'kinematics_parameters_file'
    parameter MUST point to a .yaml file containing the appropriate values for
    the targetted robot.

    If using the UniversalRobots/Universal_Robots_ROS_Driver, follow the steps
    described in the readme of that repository to extract the kinematic
    calibration from the controller and generate the required .yaml file.

    Main author of the migration to yaml configs: Ludovic Delval.

    Contributors to previous versions (in no particular order):

     - Felix Messmer
     - Kelsey Hawkins
     - Wim Meeussen
     - Shaun Edwards
     - Nadia Hammoudeh Garcia
     - Dave Hershberger
     - G. vd. Hoorn
     - Philip Long
     - Dave Coleman
     - Miguel Prada
     - Mathias Luedtke
     - Marcel Schnirring
     - Felix von Drigalski
     - Felix Exner
     - Jimmy Da Silva
     - Ajit Krisshna N L
     - Muhammad Asif Rana

  Edited by Emanuel Huber
  -->
  <!-- links: main serial chain -->

  <!-- define the ur5e's position and orientation in the world coordinate system -->
  <link name="world"/>

  <joint name="world_joint" type="fixed">
    <parent link="world"/>
    <child link="base_link"/>
    <!-- TODO: check base_link name of robot -->
    <origin rpy="0.0 0.0 0.0" xyz="0.0 0.0 0.0"/>
  </joint>

  <link name="base_link"/>

  <joint name="basejoint" type="fixed">
    <parent link="base_link"/>
    <child link="ur5e_link0"/>
    <!-- 'base_link' is REP-103 aligned (so X+ forward), while the internal
           frames of the robot/controller have X+ pointing backwards.
           Use the joint between 'base_link' and 'ur5e_link0' (a dummy
           link/frame) to introduce the necessary rotation over Z (of pi rad).
      -->
    <origin rpy="0 0 3.14159265359" xyz="0 0 0"/>
  </joint>

  <link name="ur5e_link0">
    <visual>
      <origin rpy="0 0 3.14159265359" xyz="0 0 0"/>
      <geometry>
        <mesh filename="/media/daten/Projekte/Studium/Master/Masterarbeit_SS2024/2DOF_Manipulator/MA24_simulink/stl_files/Meshes_Ur5e/visual/base.dae"/>
      </geometry>
      <material name="LightGrey">
        <color rgba="0.7 0.7 0.7 1.0"/>
      </material>
    </visual>
    <collision>
      <origin rpy="0 0 3.14159265359" xyz="0 0 0"/>
      <geometry>
        <mesh filename="/media/daten/Projekte/Studium/Master/Masterarbeit_SS2024/2DOF_Manipulator/MA24_simulink/stl_files/Meshes_Ur5e/collision/base.stl"/>
      </geometry>
    </collision>
    <inertial>
      <mass value="4.0"/>
      <origin rpy="0 0 0" xyz="0 0 0"/>
      <inertia ixx="0.00443333156" ixy="0.0" ixz="0.0" iyy="0.00443333156" iyz="0.0" izz="0.0072"/>
    </inertial>
  </link>

  <joint name="ur5e_joint1" type="revolute">
    <parent link="ur5e_link0"/>
    <child link="ur5e_link1"/>
    <origin rpy="0 0 0" xyz="0 0 0.1625"/>
    <axis xyz="0 0 1"/>
    <limit effort="150.0" lower="-6.28318530718" upper="6.28318530718" velocity="3.14159265359"/>
    <dynamics damping="0" friction="0"/>
  </joint>

  <link name="ur5e_link1">
    <visual>
      <origin rpy="0 0 3.14159265359" xyz="0 0 0"/>
      <geometry>
        <mesh filename="/media/daten/Projekte/Studium/Master/Masterarbeit_SS2024/2DOF_Manipulator/MA24_simulink/stl_files/Meshes_Ur5e/visual/shoulder.dae"/>
      </geometry>
      <material name="LightGrey">
        <color rgba="0.7 0.7 0.7 1.0"/>
      </material>
    </visual>
    <collision>
      <origin rpy="0 0 3.14159265359" xyz="0 0 0"/>
      <geometry>
        <mesh filename="/media/daten/Projekte/Studium/Master/Masterarbeit_SS2024/2DOF_Manipulator/MA24_simulink/stl_files/Meshes_Ur5e/collision/shoulder.stl"/>
      </geometry>
    </collision>
    <inertial>
      <mass value="3.7"/>
      <origin rpy="0 0 0" xyz="0 0 0"/>
      <inertia ixx="0.010267495893" ixy="0.0" ixz="0.0" iyy="0.010267495893" iyz="0.0" izz="0.00666"/>
    </inertial>
  </link>

  <joint name="ur5e_joint2" type="revolute">
    <parent link="ur5e_link1"/>
    <child link="ur5e_link2"/>
    <origin rpy="1.570796327 0 0" xyz="0 0 0"/>
    <axis xyz="0 0 1"/>
    <limit effort="150.0" lower="-6.28318530718" upper="6.28318530718" velocity="3.14159265359"/>
    <dynamics damping="0" friction="0"/>
  </joint>

  <link name="ur5e_link2">
    <visual>
      <origin rpy="1.57079632679 0 -1.57079632679" xyz="0 0 0.138"/>
      <geometry>
        <mesh filename="/media/daten/Projekte/Studium/Master/Masterarbeit_SS2024/2DOF_Manipulator/MA24_simulink/stl_files/Meshes_Ur5e/visual/upperarm.dae"/>
      </geometry>
      <material name="LightGrey">
        <color rgba="0.7 0.7 0.7 1.0"/>
      </material>
    </visual>
    <collision>
      <origin rpy="1.57079632679 0 -1.57079632679" xyz="0 0 0.138"/>
      <geometry>
        <mesh filename="/media/daten/Projekte/Studium/Master/Masterarbeit_SS2024/2DOF_Manipulator/MA24_simulink/stl_files/Meshes_Ur5e/collision/upperarm.stl"/>
      </geometry>
    </collision>
    <inertial>
      <mass value="8.393"/>
      <origin rpy="0 1.57079632679 0" xyz="-0.2125 0.0 0.138"/>
      <inertia ixx="0.133885781862" ixy="0.0" ixz="0.0" iyy="0.133885781862" iyz="0.0" izz="0.0151074"/>
    </inertial>
  </link>

  <joint name="ur5e_joint3" type="revolute">
    <parent link="ur5e_link2"/>
    <child link="ur5e_link3"/>
    <origin rpy="0 0 0" xyz="-0.425 0 0"/>
    <axis xyz="0 0 1"/>
    <limit effort="150.0" lower="-3.14159265359" upper="3.14159265359" velocity="3.14159265359"/>
    <dynamics damping="0" friction="0"/>
  </joint>

  <link name="ur5e_link3">
    <visual>
      <origin rpy="1.57079632679 0 -1.57079632679" xyz="0 0 0.007"/>
      <geometry>
        <mesh filename="/media/daten/Projekte/Studium/Master/Masterarbeit_SS2024/2DOF_Manipulator/MA24_simulink/stl_files/Meshes_Ur5e/visual/forearm.dae"/>
      </geometry>
      <material name="LightGrey">
        <color rgba="0.7 0.7 0.7 1.0"/>
      </material>
    </visual>
    <collision>
      <origin rpy="1.57079632679 0 -1.57079632679" xyz="0 0 0.007"/>
      <geometry>
        <mesh filename="/media/daten/Projekte/Studium/Master/Masterarbeit_SS2024/2DOF_Manipulator/MA24_simulink/stl_files/Meshes_Ur5e/collision/forearm.stl"/>
      </geometry>
    </collision>
    <inertial>
      <mass value="2.275"/>
      <origin rpy="0 1.57079632679 0" xyz="-0.1961 0.0 0.007"/>
      <inertia ixx="0.0312093550996" ixy="0.0" ixz="0.0" iyy="0.0312093550996" iyz="0.0" izz="0.004095"/>
    </inertial>
  </link>

  <joint name="ur5e_joint4" type="revolute">
    <parent link="ur5e_link3"/>
    <child link="ur5e_link4"/>
    <origin rpy="0 0 0" xyz="-0.3922 0 0.1333"/>
    <axis xyz="0 0 1"/>
    <limit effort="28.0" lower="-6.28318530718" upper="6.28318530718" velocity="3.14159265359"/>
    <dynamics damping="0" friction="0"/>
  </joint>

  <link name="ur5e_link4">
    <visual>
      <!-- TODO: Move this to a parameter -->
      <origin rpy="1.57079632679 0 0" xyz="0 0 -0.127"/>
      <geometry>
        <mesh filename="/media/daten/Projekte/Studium/Master/Masterarbeit_SS2024/2DOF_Manipulator/MA24_simulink/stl_files/Meshes_Ur5e/visual/wrist1.dae"/>
      </geometry>
      <material name="LightGrey">
        <color rgba="0.7 0.7 0.7 1.0"/>
      </material>
    </visual>
    <collision>
      <origin rpy="1.57079632679 0 0" xyz="0 0 -0.127"/>
      <geometry>
        <mesh filename="/media/daten/Projekte/Studium/Master/Masterarbeit_SS2024/2DOF_Manipulator/MA24_simulink/stl_files/Meshes_Ur5e/collision/wrist1.stl"/>
      </geometry>
    </collision>
    <inertial>
      <mass value="1.219"/>
      <origin rpy="0 0 0" xyz="0 0 0"/>
      <inertia ixx="0.00255989897604" ixy="0.0" ixz="0.0" iyy="0.00255989897604" iyz="0.0" izz="0.0021942"/>
    </inertial>
  </link>

  <joint name="ur5e_joint5" type="revolute">
    <parent link="ur5e_link4"/>
    <child link="ur5e_link5"/>
    <origin rpy="1.570796327 0 0" xyz="0 -0.0997 -2.0448811823e-11"/>
    <axis xyz="0 0 1"/>
    <limit effort="28.0" lower="-6.28318530718" upper="6.28318530718" velocity="3.14159265359"/>
    <dynamics damping="0" friction="0"/>
  </joint>

  <link name="ur5e_link5">
    <visual>
      <origin rpy="0 0 0" xyz="0 0 -0.0997"/>
      <geometry>
        <mesh filename="/media/daten/Projekte/Studium/Master/Masterarbeit_SS2024/2DOF_Manipulator/MA24_simulink/stl_files/Meshes_Ur5e/visual/wrist2.dae"/>
      </geometry>
      <material name="LightGrey">
        <color rgba="0.7 0.7 0.7 1.0"/>
      </material>
    </visual>
    <collision>
      <origin rpy="0 0 0" xyz="0 0 -0.0997"/>
      <geometry>
        <mesh filename="/media/daten/Projekte/Studium/Master/Masterarbeit_SS2024/2DOF_Manipulator/MA24_simulink/stl_files/Meshes_Ur5e/collision/wrist2.stl"/>
      </geometry>
    </collision>
    <inertial>
      <mass value="1.219"/>
      <origin rpy="0 0 0" xyz="0 0 0"/>
      <inertia ixx="0.00255989897604" ixy="0.0" ixz="0.0" iyy="0.00255989897604" iyz="0.0" izz="0.0021942"/>
    </inertial>
  </link>

  <joint name="ur5e_joint6" type="revolute">
    <parent link="ur5e_link5"/>
    <child link="ur5e_link6"/>
    <origin rpy="1.57079632659 3.14159265359 3.14159265359" xyz="0 0.0996 -2.04283014801e-11"/>
    <axis xyz="0 0 1"/>
    <limit effort="28.0" lower="-6.28318530718" upper="6.28318530718" velocity="3.14159265359"/>
    <dynamics damping="0" friction="0"/>
  </joint>

  <link name="ur5e_link6">
    <visual>
      <origin rpy="1.57079632679 0 0" xyz="0 0 -0.0989"/>
      <geometry>
        <mesh filename="/media/daten/Projekte/Studium/Master/Masterarbeit_SS2024/2DOF_Manipulator/MA24_simulink/stl_files/Meshes_Ur5e/visual/wrist3.dae"/>
      </geometry>
      <material name="LightGrey">
        <color rgba="0.7 0.7 0.7 1.0"/>
      </material>
    </visual>
    <collision>
      <origin rpy="1.57079632679 0 0" xyz="0 0 -0.0989"/>
      <geometry>
        <mesh filename="/media/daten/Projekte/Studium/Master/Masterarbeit_SS2024/2DOF_Manipulator/MA24_simulink/stl_files/Meshes_Ur5e/collision/wrist3.stl"/>
      </geometry>
    </collision>
    <inertial>
      <mass value="0.1879"/>
      <origin rpy="0 0 0" xyz="0.0 0.0 -0.0229"/>
      <inertia ixx="9.89041005217e-05" ixy="0.0" ixz="0.0" iyy="9.89041005217e-05" iyz="0.0" izz="0.0001321171875"/>
    </inertial>
  </link>
  <!-- joints: main serial chain -->
</robot>