<?xml version="1.0" encoding="utf-8" ?>
<!-- =================================================================================== -->
<!-- |    This document was autogenerated by xacro from                                  -->
<!-- |    /home/james/wrc_ws/src/ur_robotiq/ur5e_2f85/ur5e_2f85_description/urdf/ur5e_2f85_joint_limited_robot.urdf.xacro | -->
<!-- |    and updated by Emanuel Huber                                                   -->
<!-- |    EDITING THIS FILE BY HAND IS NOT RECOMMENDED (...)                           | -->
<!-- =================================================================================== -->
<robot name="ur5e_robot" xmlns:xacro="http://wiki.ros.org/xacro">

    <link name="world" />

    <joint name="world_joint" type="fixed">
        <parent link="world" />
        <child link="base_link" />
        <origin rpy="0.0 0.0 0.0" xyz="0.0 0.0 0.0" />
    </joint>

    <link name="base_link">
        <visual>
            <geometry>
                <mesh filename="ur5e-link0_con.stl" />
            </geometry>
            <material name="con_color">
                <color rgba="0.0157 0.0157 0.0157 1.0" />
            </material>
        </visual>
        <visual>
            <geometry>
                <mesh filename="ur5e-link0_rod.stl" />
            </geometry>
            <material name="rod_color">
                <color rgba="0.7255 0.7255 0.7255 1.0" />
            </material>
        </visual>
        <collision>
            <geometry>
                <mesh filename="collision_base.stl" />
            </geometry>
        </collision>
        
        <inertial>
            <mass value="4.0" />
            <origin rpy="0 0 0" xyz="0.0 0.0 0.0" />
            <inertia ixx="0.00443333156" ixy="0.0" ixz="0.0" iyy="0.00443333156" iyz="0.0" izz="0.0072" />
        </inertial>
    </link>

    <!-- Joint 1: Base joint -->
    <joint name="ur5e_joint1" type="revolute">
        <parent link="base_link" />
        <child link="ur5e_link1" />
        <origin rpy="0.0 0.0 0.0" xyz="0.0 0.0 0.1625" />
        <axis xyz="0 0 1" />
        <limit effort="150.0" lower="-6.28318530718" upper="6.28318530718" velocity="3.14159265359" />
        <dynamics damping="0.0" friction="0.0" />
    </joint>

    <link name="ur5e_link1">
        <visual>
            <geometry>
                <mesh filename="ur5e-link1_cap.stl" />
            </geometry>
            <material name="cap_color">
                <color rgba="0.5529 0.7098 0.8353 1.0" />
            </material>
        </visual>
        <visual>
            <geometry>
                <mesh filename="ur5e-link1_con.stl" />
            </geometry>
            <material name="con_color">
                <color rgba="0.0157 0.0157 0.0157 1.0" />
            </material>
        </visual>
        <visual>
            <geometry>
                <mesh filename="ur5e-link1_joi.stl" />
            </geometry>
            <material name="joi_color">
                <color rgba="0.4078 0.4078 0.4078 1.0" />
            </material>
        </visual>
        <collision>
            <geometry>
                <mesh filename="collision_shoulder.stl" />
            </geometry>
        </collision>
        
        <inertial>
            <mass value="3.7" />
            <origin rpy="0 0 0" xyz="0.0 0.0 0.0" />
            <inertia ixx="0.010267495893" ixy="0.0" ixz="0.0" iyy="0.010267495893" iyz="0.0" izz="0.00666" />
        </inertial>
    </link>

    <!-- Joint 2: Shoulder joint -->
    <joint name="ur5e_joint2" type="revolute">
        <parent link="ur5e_link1" />
        <child link="ur5e_link2" />
        <origin rpy="0.0 1.57079632679 0.0" xyz="0.0 0.138 0.0" />
        <axis xyz="0 1 0" />
        <limit effort="150.0" lower="-6.28318530718" upper="6.28318530718" velocity="3.14159265359" />
        <dynamics damping="0.0" friction="0.0" />
    </joint>

    <link name="ur5e_link2">
        <visual> 
            <geometry>
                <mesh filename="ur5e-link2_cap1.stl" />
            </geometry>
            <material name="cap_color">
                <color rgba="0.5529 0.7098 0.8353 1.0" />
            </material>
        </visual>
        <visual>
            <geometry>
                <mesh filename="ur5e-link2_cap2.stl" />
            </geometry>
            <material name="cap_color">
                <color rgba="0.5529 0.7098 0.8353 1.0" />
            </material>
        </visual>
        <visual>
            <geometry>
                <mesh filename="ur5e-link2_con1.stl" />
            </geometry>
            <material name="con_color">
                <color rgba="0.0157 0.0157 0.0157 1.0" />
            </material>
        </visual>
        <visual>
            <geometry>
                <mesh filename="ur5e-link2_con2.stl" />
            </geometry>
            <material name="con_color">
                <color rgba="0.0157 0.0157 0.0157 1.0" />
            </material>
        </visual>
        <visual>
            <geometry>
                <mesh filename="ur5e-link2_con3.stl" />
            </geometry>
            <material name="con_color">
                <color rgba="0.0157 0.0157 0.0157 1.0" />
            </material>
        </visual>
        <visual>
            <geometry>
                <mesh filename="ur5e-link2_joi1.stl" />
            </geometry>
            <material name="joi_color">
                <color rgba="0.4078 0.4078 0.4078 1.0" />
            </material>
        </visual>
        <visual>
            <geometry>
                <mesh filename="ur5e-link2_joi2.stl" />
            </geometry>
            <material name="joi_color">
                <color rgba="0.4078 0.4078 0.4078 1.0" />
            </material>
        </visual>
        <visual>
            <geometry>
                <mesh filename="ur5e-link2_rod.stl" />
            </geometry>
            <material name="rod_color">
                <color rgba="0.7255 0.7255 0.7255 1.0" />
            </material>
        </visual>
        <collision>
            <geometry>
                <mesh filename="collision_upperarm.stl" />
            </geometry>
        </collision>
        
        <inertial>
            <mass value="8.393" />
            <origin rpy="0 0 0" xyz="0.0 0.0 0.2125" />
            <inertia ixx="0.133885781862" ixy="0.0" ixz="0.0" iyy="0.133885781862" iyz="0.0" izz="0.0151074" />
        </inertial>
    </link>

    <!-- Joint 3: Elbow joint -->
    <joint name="ur5e_joint3" type="revolute">
        <parent link="ur5e_link2" />
        <child link="ur5e_link3" />
        <origin rpy="0.0 0.0 0.0" xyz="0.0 -0.131 0.425" />
        <axis xyz="0 1 0" />
        <limit effort="150.0" lower="-6.28318530718" upper="6.28318530718" velocity="3.14159265359" />
        <dynamics damping="0.0" friction="0.0" />
    </joint>

    <link name="ur5e_link3">
        <visual>
            <geometry>
                <mesh filename="ur5e-link3_cap.stl" />
            </geometry>
            <material name="cap_color">
                <color rgba="0.5529 0.7098 0.8353 1.0" />
            </material>
        </visual>
        <visual>
            <geometry>
                <mesh filename="ur5e-link3_con1.stl" />
            </geometry>
            <material name="con_color">
                <color rgba="0.0157 0.0157 0.0157 1.0" />
            </material>
        </visual>
        <visual>
            <geometry>
                <mesh filename="ur5e-link3_con2.stl" />
            </geometry>
            <material name="con_color">
                <color rgba="0.0157 0.0157 0.0157 1.0" />
            </material>
        </visual>
        <visual>
            <geometry>
                <mesh filename="ur5e-link3_con3.stl" />
            </geometry>
            <material name="con_color">
                <color rgba="0.0157 0.0157 0.0157 1.0" />
            </material>
        </visual>
        <visual>
            <geometry>
                <mesh filename="ur5e-link3_joi1.stl" />
            </geometry>
            <material name="joi_color">
                <color rgba="0.4078 0.4078 0.4078 1.0" />
            </material>
        </visual>
        <visual>
            <geometry>
                <mesh filename="ur5e-link3_joi2.stl" />
            </geometry>
            <material name="joi_color">
                <color rgba="0.4078 0.4078 0.4078 1.0" />
            </material>
        </visual>
        <visual>
            <geometry>
                <mesh filename="ur5e-link3_rod.stl" />
            </geometry>
            <material name="rod_color">
                <color rgba="0.7255 0.7255 0.7255 1.0" />
            </material>
        </visual>
        <collision>
            <geometry>
                <mesh filename="collision_forearm.stl" />
            </geometry>
        </collision>
        
        <inertial>
            <mass value="2.275" />
            <origin rpy="0 0 0" xyz="0.0 0.0 0.196" />
            <inertia ixx="0.0311796208615" ixy="0.0" ixz="0.0" iyy="0.0311796208615" iyz="0.0" izz="0.004095" />
        </inertial>
    </link>

    <!-- Joint 4: Wrist 1 joint -->
    <joint name="ur5e_joint4" type="revolute">
        <parent link="ur5e_link3" />
        <child link="ur5e_link4" />
        <origin rpy="0.0 1.57079632679 0.0" xyz="0.0 0.0 0.392" />
        <axis xyz="0 1 0" />
        <limit effort="28.0" lower="-6.28318530718" upper="6.28318530718" velocity="6.28" />
        <dynamics damping="0.0" friction="0.0" />
    </joint>

    <link name="ur5e_link4">
        <visual>
            <geometry>
                <mesh filename="ur5e-link4_cap.stl" />
            </geometry>
            <material name="cap_color">
                <color rgba="0.5529 0.7098 0.8353 1.0" />
            </material>
        </visual>
        <visual>
            <geometry>
                <mesh filename="ur5e-link4_con.stl" />
            </geometry>
            <material name="con_color">
                <color rgba="0.0157 0.0157 0.0157 1.0" />
            </material>
        </visual>
        <visual>
            <geometry>
                <mesh filename="ur5e-link4_joi.stl" />
            </geometry>
            <material name="joi_color">
                <color rgba="0.4078 0.4078 0.4078 1.0" />
            </material>
        </visual>
        <collision>
            <geometry>
                <mesh filename="collision_wrist1.stl" />
            </geometry>
        </collision>
        
        <inertial>
            <mass value="1.219" />
            <origin rpy="0 0 0" xyz="0.0 0.127 0.0" />
            <inertia ixx="0.00255989897604" ixy="0.0" ixz="0.0" iyy="0.00255989897604" iyz="0.0" izz="0.0021942" />
        </inertial>
    </link>

    <!-- Joint 5: Wrist 2 joint -->
    <joint name="ur5e_joint5" type="revolute">
        <parent link="ur5e_link4" />
        <child link="ur5e_link5" />
        <origin rpy="0.0 0.0 0.0" xyz="0.0 0.127 0.0" />
        <axis xyz="0 0 1" />
        <limit effort="28.0" lower="-6.28318530718" upper="6.28318530718" velocity="6.28" />
        <dynamics damping="0.0" friction="0.0" />
    </joint>

    <link name="ur5e_link5">
        <visual>
            <geometry>
                <mesh filename="ur5e-link5_cap.stl" />
            </geometry>
            <material name="cap_color">
                <color rgba="0.5529 0.7098 0.8353 1.0" />
            </material>
        </visual>
        <visual>
            <geometry>
                <mesh filename="ur5e-link5_con.stl" />
            </geometry>
            <material name="con_color">
                <color rgba="0.0157 0.0157 0.0157 1.0" />
            </material>
        </visual>
        <visual>
            <geometry>
                <mesh filename="ur5e-link5_joi.stl" />
            </geometry>
            <material name="joi_color">
                <color rgba="0.4078 0.4078 0.4078 1.0" />
            </material>
        </visual>
        <collision>
            <geometry>
                <mesh filename="collision_wrist2.stl" />
            </geometry>
        </collision>
        
        <inertial>
            <mass value="1.219" />
            <origin rpy="0 0 0" xyz="0.0 0.0 0.1" />
            <inertia ixx="0.00255989897604" ixy="0.0" ixz="0.0" iyy="0.00255989897604" iyz="0.0" izz="0.0021942" />
        </inertial>
    </link>

    <!-- JOINT 6: Wrist 3 joint -->
    <joint name="ur5e_joint6" type="revolute">
        <parent link="ur5e_link5" />
        <child link="ur5e_link6" />
        <origin rpy="0.0 0.0 0.0" xyz="0.0 0.0 0.1" />
        <axis xyz="0 1 0" />
        <limit effort="28.0" lower="-6.28318530718" upper="6.28318530718" velocity="6.28" />
        <dynamics damping="0.0" friction="0.0" />
    </joint>

    <link name="ur5e_link6">
        <visual>
            <geometry>
                <mesh filename="ur5e-link6_rod.stl" />
            </geometry>
            <material name="rod_color">
                <color rgba="0.7255 0.7255 0.7255 1.0" />
            </material>
        </visual>
        <collision>
            <geometry>
                <mesh filename="collision_wrist3.stl" />
            </geometry>
        </collision>
        
        <inertial>
            <mass value="0.1879" />
            <origin rpy="1.57079632679 0 0" xyz="0.0 0.0771 0.0" />
            <inertia ixx="9.89041005217e-05" ixy="0.0" ixz="0.0" iyy="9.89041005217e-05" iyz="0.0" izz="0.0001321171875" />
        </inertial>
    </link>

    <!-- TCP JOINT -->
    <joint name="TCP_fixed_joint" type="fixed">
        <parent link="ur5e_link6" />
        <child link="ur5e_tcp" />
        <origin rpy="0.0 0.0 1.57079632679" xyz="0.0 0.1 0.0" />
    </joint>

    <link name="ur5e_tcp">
        <collision>
            <geometry>
                <box size="0.01 0.01 0.01" />
            </geometry>
            <origin rpy="0 0 0" xyz="-0.01 0 0" />
        </collision>
        
        <inertial>
            <mass value="0.1" />
            <inertia ixx="0.03" iyy="0.03" izz="0.03" ixy="0.0" ixz="0.0" iyz="0.0" />
        </inertial>
    </link>

    <mujoco>
            <compiler 
            meshdir="/media/daten/Projekte/Studium/Master/Masterarbeit_SS2024/2DOF_Manipulator/MA24_simulink/stl_files/Meshes_ur5e" 
            balanceinertia="true" 
            discardvisual="false"
            discardcollision="true"
            />
    </mujoco>
</robot>