<mujoco model="ur5e_robot">
  <compiler angle="radian" meshdir="../../stl_files/Meshes_ur5e/" autolimits="true"/>
  <statistic meansize="0.227096" extent="1.07125" center="0.381442 0.227296 0.162489"/>
  
  <visual>
    <headlight diffuse="0.6 0.6 0.6" ambient="0.3 0.3 0.3" specular="0 0 0"/>
    <rgba haze="0.15 0.25 0.35 1"/>
    <global azimuth="120" elevation="-20"/>
  </visual>
  
  <default>
	<include file="./ur5e_robot_default.xml"/>
  </default>
  
  <asset>
    <texture type="skybox" builtin="gradient" rgb1="0.3 0.5 0.7" rgb2="0 0 0" width="512" height="3072"/>
    <texture type="2d" name="groundplane" builtin="checker" mark="edge" rgb1="0.2 0.3 0.4" rgb2="0.1 0.2 0.3"
      markrgb="0.8 0.8 0.8" width="300" height="300"/>
    <material name="groundplane" texture="groundplane" texuniform="true" texrepeat="5 5" reflectance="0.2"/>
  </asset>
  
  <asset>
    <mesh name="ur5e-link0_con" file="ur5e-link0_con.stl"/>
    <mesh name="ur5e-link0_rod" file="ur5e-link0_rod.stl"/>
    <mesh name="collision_base" file="collision_base.stl"/>
    <mesh name="ur5e-link1_cap" file="ur5e-link1_cap.stl"/>
    <mesh name="ur5e-link1_con" file="ur5e-link1_con.stl"/>
    <mesh name="ur5e-link1_joi" file="ur5e-link1_joi.stl"/>
    <mesh name="collision_shoulder" file="collision_shoulder.stl"/>
    <mesh name="ur5e-link2_cap1" file="ur5e-link2_cap1.stl"/>
    <mesh name="ur5e-link2_cap2" file="ur5e-link2_cap2.stl"/>
    <mesh name="ur5e-link2_con1" file="ur5e-link2_con1.stl"/>
    <mesh name="ur5e-link2_con2" file="ur5e-link2_con2.stl"/>
    <mesh name="ur5e-link2_con3" file="ur5e-link2_con3.stl"/>
    <mesh name="ur5e-link2_joi1" file="ur5e-link2_joi1.stl"/>
    <mesh name="ur5e-link2_joi2" file="ur5e-link2_joi2.stl"/>
    <mesh name="ur5e-link2_rod" file="ur5e-link2_rod.stl"/>
    <mesh name="collision_upperarm" file="collision_upperarm.stl"/>
    <mesh name="ur5e-link3_cap" file="ur5e-link3_cap.stl"/>
    <mesh name="ur5e-link3_con1" file="ur5e-link3_con1.stl"/>
    <mesh name="ur5e-link3_con2" file="ur5e-link3_con2.stl"/>
    <mesh name="ur5e-link3_con3" file="ur5e-link3_con3.stl"/>
    <mesh name="ur5e-link3_joi1" file="ur5e-link3_joi1.stl"/>
    <mesh name="ur5e-link3_joi2" file="ur5e-link3_joi2.stl"/>
    <mesh name="ur5e-link3_rod" file="ur5e-link3_rod.stl"/>
    <mesh name="collision_forearm" file="collision_forearm.stl"/>
    <mesh name="ur5e-link4_cap" file="ur5e-link4_cap.stl"/>
    <mesh name="ur5e-link4_con" file="ur5e-link4_con.stl"/>
    <mesh name="ur5e-link4_joi" file="ur5e-link4_joi.stl"/>
    <mesh name="collision_wrist1" file="collision_wrist1.stl"/>
    <mesh name="ur5e-link5_cap" file="ur5e-link5_cap.stl"/>
    <mesh name="ur5e-link5_con" file="ur5e-link5_con.stl"/>
    <mesh name="ur5e-link5_joi" file="ur5e-link5_joi.stl"/>
    <mesh name="collision_wrist2" file="collision_wrist2.stl"/>
    <mesh name="ur5e-link6_rod" file="ur5e-link6_rod.stl"/>
    <mesh name="collision_wrist3" file="collision_wrist3.stl"/>
  </asset>
  
  <worldbody>
     <light pos="0 0 1.5" dir="0 0 -1" directional="true"/>
    <geom name="floor" size="0 0 0.05" pos="0 0 0" quat="0 0 0 1" type="plane"  material="groundplane"/>
    <geom type="mesh" class="visual" contype="0" conaffinity="0" density="0" rgba="0.0157 0.0157 0.0157 1" mesh="ur5e-link0_con"/>
    <geom type="mesh" class="visual" contype="0" conaffinity="0" density="0" rgba="0.7255 0.7255 0.7255 1" mesh="ur5e-link0_rod"/>
    <geom type="mesh" class="collision" rgba="0.7255 0.7255 0.7255 1" mesh="collision_base"/>
    <body name="ur5e_link1" pos="0 0 0.1625">
      <inertial pos="0 0 0" mass="3.7" diaginertia="0.0102675 0.0102675 0.00666"/>
      <joint name="ur5e_joint1" pos="0 0 0" axis="0 0 1" range="-6.28319 6.28319"/>
      <geom type="mesh" class="visual" contype="0" conaffinity="0" density="0" rgba="0.5529 0.7098 0.8353 1" mesh="ur5e-link1_cap"/>
      <geom type="mesh" class="visual" contype="0" conaffinity="0" density="0" rgba="0.0157 0.0157 0.0157 1" mesh="ur5e-link1_con"/>
      <geom type="mesh" class="visual" contype="0" conaffinity="0" density="0" rgba="0.4078 0.4078 0.4078 1" mesh="ur5e-link1_joi"/>
      <geom type="mesh" class="collision" rgba="0.4078 0.4078 0.4078 1" mesh="collision_shoulder"/>
      <body name="ur5e_link2" pos="0 0.138 0" quat="0.707107 0 0.707107 0">
        <inertial pos="0 0 0.2125" mass="8.393" diaginertia="0.133886 0.133886 0.0151074"/>
        <joint name="ur5e_joint2" pos="0 0 0" axis="0 1 0" range="-6.28319 6.28319"/>
        <geom type="mesh" class="visual" contype="0" conaffinity="0" density="0" rgba="0.5529 0.7098 0.8353 1" mesh="ur5e-link2_cap1"/>
        <geom type="mesh" class="visual" contype="0" conaffinity="0" density="0" rgba="0.5529 0.7098 0.8353 1" mesh="ur5e-link2_cap2"/>
        <geom type="mesh" class="visual" contype="0" conaffinity="0" density="0" rgba="0.0157 0.0157 0.0157 1" mesh="ur5e-link2_con1"/>
        <geom type="mesh" class="visual" contype="0" conaffinity="0" density="0" rgba="0.0157 0.0157 0.0157 1" mesh="ur5e-link2_con2"/>
        <geom type="mesh" class="visual" contype="0" conaffinity="0" density="0" rgba="0.0157 0.0157 0.0157 1" mesh="ur5e-link2_con3"/>
        <geom type="mesh" class="visual" contype="0" conaffinity="0" density="0" rgba="0.4078 0.4078 0.4078 1" mesh="ur5e-link2_joi1"/>
        <geom type="mesh" class="visual" contype="0" conaffinity="0" density="0" rgba="0.4078 0.4078 0.4078 1" mesh="ur5e-link2_joi2"/>
        <geom type="mesh" class="visual" contype="0" conaffinity="0" density="0" rgba="0.7255 0.7255 0.7255 1" mesh="ur5e-link2_rod"/>
        <geom type="mesh" class="collision" rgba="0.7255 0.7255 0.7255 1" mesh="collision_upperarm"/>
        <body name="ur5e_link3" pos="0 -0.131 0.425">
          <inertial pos="0 0 0.196" mass="2.275" diaginertia="0.0311796 0.0311796 0.004095"/>
          <joint name="ur5e_joint3" pos="0 0 0" axis="0 1 0" range="-6.28319 6.28319"/>
          <geom type="mesh" class="visual" contype="0" conaffinity="0" density="0" rgba="0.5529 0.7098 0.8353 1" mesh="ur5e-link3_cap"/>
          <geom type="mesh" class="visual" contype="0" conaffinity="0" density="0" rgba="0.0157 0.0157 0.0157 1" mesh="ur5e-link3_con1"/>
          <geom type="mesh" class="visual" contype="0" conaffinity="0" density="0" rgba="0.0157 0.0157 0.0157 1" mesh="ur5e-link3_con2"/>
          <geom type="mesh" class="visual" contype="0" conaffinity="0" density="0" rgba="0.0157 0.0157 0.0157 1" mesh="ur5e-link3_con3"/>
          <geom type="mesh" class="visual" contype="0" conaffinity="0" density="0" rgba="0.4078 0.4078 0.4078 1" mesh="ur5e-link3_joi1"/>
          <geom type="mesh" class="visual" contype="0" conaffinity="0" density="0" rgba="0.4078 0.4078 0.4078 1" mesh="ur5e-link3_joi2"/>
          <geom type="mesh" class="visual" contype="0" conaffinity="0" density="0" rgba="0.7255 0.7255 0.7255 1" mesh="ur5e-link3_rod"/>
          <geom type="mesh" class="collision" rgba="0.7255 0.7255 0.7255 1" mesh="collision_forearm"/>
          <body name="ur5e_link4" pos="0 0 0.392" quat="0.707107 0 0.707107 0">
            <inertial pos="0 0.127 0" mass="1.219" diaginertia="0.0025599 0.0025599 0.0021942"/>
            <joint name="ur5e_joint4" pos="0 0 0" axis="0 1 0" range="-6.28319 6.28319"/>
            <geom type="mesh" class="visual" contype="0" conaffinity="0" density="0" rgba="0.5529 0.7098 0.8353 1" mesh="ur5e-link4_cap"/>
            <geom type="mesh" class="visual" contype="0" conaffinity="0" density="0" rgba="0.0157 0.0157 0.0157 1" mesh="ur5e-link4_con"/>
            <geom type="mesh" class="visual" contype="0" conaffinity="0" density="0" rgba="0.4078 0.4078 0.4078 1" mesh="ur5e-link4_joi"/>
            <geom type="mesh" class="collision" rgba="0.4078 0.4078 0.4078 1" mesh="collision_wrist1"/>
            <body name="ur5e_link5" pos="0 0.127 0">
              <inertial pos="0 0 0.1" mass="1.219" diaginertia="0.0025599 0.0025599 0.0021942"/>
              <joint name="ur5e_joint5" pos="0 0 0" axis="0 0 1" range="-6.28319 6.28319"/>
              <geom type="mesh" class="visual" contype="0" conaffinity="0" density="0" rgba="0.5529 0.7098 0.8353 1" mesh="ur5e-link5_cap"/>
              <geom type="mesh" class="visual" contype="0" conaffinity="0" density="0" rgba="0.0157 0.0157 0.0157 1" mesh="ur5e-link5_con"/>
              <geom type="mesh" class="visual" contype="0" conaffinity="0" density="0" rgba="0.4078 0.4078 0.4078 1" mesh="ur5e-link5_joi"/>
              <geom type="mesh" class="collision" rgba="0.4078 0.4078 0.4078 1" mesh="collision_wrist2"/>
              <body name="ur5e_link6" pos="0 0 0.1">
                <inertial pos="0 0.0850542 0" quat="0.707107 0.707107 0 0" mass="0.2879" diaginertia="0.0301331 0.0301331 0.0301321"/>
                <joint name="ur5e_joint6" pos="0 0 0" axis="0 1 0" range="-6.28319 6.28319"/>
                <geom type="mesh" class="visual" contype="0" conaffinity="0" density="0" rgba="0.7255 0.7255 0.7255 1" mesh="ur5e-link6_rod"/>
                <geom type="mesh" class="collision" rgba="0.7255 0.7255 0.7255 1" mesh="collision_wrist3"/>
                <geom size="0.005 0.005 0.005" pos="0 0.09 0" quat="0.707107 0 0 0.707107" type="box"/>
              </body>
            </body>
          </body>
        </body>
      </body>
    </body>
  </worldbody>
  
</mujoco>
